Workbook

Sheet Summary
A1: AI Based Chatbot – QA Test Report
A3: Environment
A4: Date | B4: 2026-10-24 10:29
A5: Repository | B5: chat-bot
A6: Branch | B6: main
A7: Commit | B7: 02f4fcc Document the demo deployment
A8: Working tree (outside qa/) | B8: M README.md
A9: OS | B9: Linux-6.8.0-1064-azure-x86_64-with-glibc2.39
A10: Python | B10: 3.12.3
A11: Backend | B11: FastAPI 0.143.0, Starlette 1.8.0, Pydantic 2.14.1, Uvicorn 0.54.0, openai 3.31.0
A12: Frontend | B12: Plain HTML/CSS/JavaScript (no build step)
A13: Test tools | B13: pytest 9.1.1, Playwright 1.64.0 + Chromium 156.0.8078.4, axe-core 4.10.2, httpx 0.28.1, openpyxl 3.1.5
A14: Node / Docker | B14: v24.21.0 / Docker version 29.8.0-1, build 88096ef00576baf72a9cb45caa45c0544c40e0a7
A15: Mode | B15: MOCK/LOCAL: CHATBOT_MODE=local (keyword retriever + extractive stand-in for the LLM); failure tests use the real openai SDK with a mocked network. No live Azure OpenAI/AI Search calls were made (no credentials; would cost money).
A17: Results by layer
A18: Layer | B18: Pass | C18: Fail | D18: Blocked | E18: Not Tested | F18: Total | G18: Pass rate
A19: Backend | B19: =COUNTIFS('Test Cases'!$B$2:$B$102,$A19,'Test Cases'!$H$2:$H$102,"Pass") | C19: =COUNTIFS('Test Cases'!$B$2:$B$102,$A19,'Test Cases'!$H$2:$H$102,"Fail") | D19: =COUNTIFS('Test Cases'!$B$2:$B$102,$A19,'Test Cases'!$H$2:$H$102,"Blocked") | E19: =COUNTIFS('Test Cases'!$B$2:$B$102,$A19,'Test Cases'!$H$2:$H$102,"Not Tested") | F19: =SUM(B19:E19) | G19: =IF(F19=0,0,B19/F19)
A20: UI | B20: =COUNTIFS('Test Cases'!$B$2:$B$102,$A20,'Test Cases'!$H$2:$H$102,"Pass") | C20: =COUNTIFS('Test Cases'!$B$2:$B$102,$A20,'Test Cases'!$H$2:$H$102,"Fail") | D20: =COUNTIFS('Test Cases'!$B$2:$B$102,$A20,'Test Cases'!$H$2:$H$102,"Blocked") | E20: =COUNTIFS('Test Cases'!$B$2:$B$102,$A20,'Test Cases'!$H$2:$H$102,"Not Tested") | F20: =SUM(B20:E20) | G20: =IF(F20=0,0,B20/F20)
A21: Front end | B21: =COUNTIFS('Test Cases'!$B$2:$B$102,$A21,'Test Cases'!$H$2:$H$102,"Pass") | C21: =COUNTIFS('Test Cases'!$B$2:$B$102,$A21,'Test Cases'!$H$2:$H$102,"Fail") | D21: =COUNTIFS('Test Cases'!$B$2:$B$102,$A21,'Test Cases'!$H$2:$H$102,"Blocked") | E21: =COUNTIFS('Test Cases'!$B$2:$B$102,$A21,'Test Cases'!$H$2:$H$102,"Not Tested") | F21: =SUM(B21:E21) | G21: =IF(F21=0,0,B21/F21)
A22: Total | B22: =SUM(B19:B21) | C22: =SUM(C19:C21) | D22: =SUM(D19:D21) | E22: =SUM(E19:E21) | F22: =SUM(F19:F21) | G22: =IF(F22=0,0,B22/F22)
A24: Results by priority
A25: Priority | B25: Pass | C25: Fail | D25: Blocked | E25: Not Tested | F25: Total | G25: Pass rate
A26: Critical | B26: =COUNTIFS('Test Cases'!$C$2:$C$102,$A26,'Test Cases'!$H$2:$H$102,"Pass") | C26: =COUNTIFS('Test Cases'!$C$2:$C$102,$A26,'Test Cases'!$H$2:$H$102,"Fail") | D26: =COUNTIFS('Test Cases'!$C$2:$C$102,$A26,'Test Cases'!$H$2:$H$102,"Blocked") | E26: =COUNTIFS('Test Cases'!$C$2:$C$102,$A26,'Test Cases'!$H$2:$H$102,"Not Tested") | F26: =SUM(B26:E26) | G26: =IF(F26=0,0,B26/F26)
A27: High | B27: =COUNTIFS('Test Cases'!$C$2:$C$102,$A27,'Test Cases'!$H$2:$H$102,"Pass") | C27: =COUNTIFS('Test Cases'!$C$2:$C$102,$A27,'Test Cases'!$H$2:$H$102,"Fail") | D27: =COUNTIFS('Test Cases'!$C$2:$C$102,$A27,'Test Cases'!$H$2:$H$102,"Blocked") | E27: =COUNTIFS('Test Cases'!$C$2:$C$102,$A27,'Test Cases'!$H$2:$H$102,"Not Tested") | F27: =SUM(B27:E27) | G27: =IF(F27=0,0,B27/F27)
A28: Medium | B28: =COUNTIFS('Test Cases'!$C$2:$C$102,$A28,'Test Cases'!$H$2:$H$102,"Pass") | C28: =COUNTIFS('Test Cases'!$C$2:$C$102,$A28,'Test Cases'!$H$2:$H$102,"Fail") | D28: =COUNTIFS('Test Cases'!$C$2:$C$102,$A28,'Test Cases'!$H$2:$H$102,"Blocked") | E28: =COUNTIFS('Test Cases'!$C$2:$C$102,$A28,'Test Cases'!$H$2:$H$102,"Not Tested") | F28: =SUM(B28:E28) | G28: =IF(F28=0,0,B28/F28)
A29: Low | B29: =COUNTIFS('Test Cases'!$C$2:$C$102,$A29,'Test Cases'!$H$2:$H$102,"Pass") | C29: =COUNTIFS('Test Cases'!$C$2:$C$102,$A29,'Test Cases'!$H$2:$H$102,"Fail") | D29: =COUNTIFS('Test Cases'!$C$2:$C$102,$A29,'Test Cases'!$H$2:$H$102,"Blocked") | E29: =COUNTIFS('Test Cases'!$C$2:$C$102,$A29,'Test Cases'!$H$2:$H$102,"Not Tested") | F29: =SUM(B29:E29) | G29: =IF(F29=0,0,B29/F29)
A30: Total | B30: =SUM(B26:B29) | C30: =SUM(C26:C29) | D30: =SUM(D26:D29) | E30: =SUM(E26:E29) | F30: =SUM(F26:F29) | G30: =IF(F30=0,0,B30/F30)
A32: Pass rate (all tests) | B32: =B22/F22
A33: Pass rate (executed: Pass+Fail) | B33: =B22/(B22+C22)
A34: Critical/High not passing | B34: =COUNTIFS('Test Cases'!$C$2:$C$102,"Critical",'Test Cases'!$H$2:$H$102,"<>Pass")+COUNTIFS('Test Cases'!$C$2:$C$102,"High",'Test Cases'!$H$2:$H$102,"<>Pass")
A35: Rule check | B35: =IF(B34=0,"All Critical and High passed","Not all Critical/High passed: Works as expected is not possible")
A37: VERDICT | B37: Works with issues
A38: Justification | B38: 54 of 57 Critical/High tests passed. 0 Critical/High failed and 3 are Blocked (they need a live Azure OpenAI model: context recall, grounding quality, prompt-injection resistance), so the 'Works as expected' rule (all Critical and High must pass) is not met. The core chat flow, validation, error handling, auth gate, uploads, XSS protection, responsiveness and accessibility all work in local/mock mode. 7 lower-priority tests failed, giving 7 defects (4 Medium, 3 Low): token not revoked on logout, rate limit/lockout bypass via X-Forwarded-For, sign-in turned off by an AUTH_MODE typo, and a typed question lost while waiting.

Sheet Test Cases
A1: ID | B1: Layer | C1: Priority | D1: Area | E1: Steps | F1: Expected Result | G1: Actual Result | H1: Status | I1: Evidence | J1: Defect
A2: BE-001 | B2: Backend | C2: Critical | D2: Existing automated tests | E2: Run `make test` equivalent: `.venv/bin/python -m pytest Code/backend -q`. | F2: All existing tests pass (exit 0). | G2: exit 0: 109 passed in 6.00s | H2: Pass | I2: $ .venv/bin/python -m pytest 'qa/tests/test_backend_live.py::test_BE_001_existing_suite' → exit 0 make test == .venv/bin/python -m pytest Code/backend -q
A3: BE-002 | B3: Backend | C3: Critical | D3: Startup | E3: Start with the documented command `cd Code/backend && uvicorn chatbot.main:app` (local mode, no .env); poll /healthz. | F3: Server healthy within a few seconds; no ERROR/WARNING/Traceback in the log. | G3: healthy after 0.55s: {'status': 'ok', 'version': '1.0.0', 'mode': 'local', 'searchSetup': 'not-applicable'}; error/warning log lines: [] | H3: Pass | I3: $ .venv/bin/python -m pytest 'qa/tests/test_backend_live.py::test_BE_002_starts_with_documented_config' → exit 0 cd Code/backend && RATE_LIMIT_PER_MINUTE=0 .venv/bin/python -m uvicorn chatbot.main:app --port 53861
A4: BE-003 | B4: Backend | C4: High | D4: Config – missing | E4: Start with CHATBOT_MODE=azure and none of the AZURE_* settings. | F4: Process refuses to start (non-zero exit) with a message naming the missing settings. | G4: exit code=1; message: RuntimeError: CHATBOT_MODE=azure but these settings are missing: AZURE_OPENAI_ENDPOINT, AZURE_SEARCH_ENDPOINT, AZURE_STORAGE_ACCOUNT_URL, AZURE_STORAGE_RESOURCE_ID; traceback printed=True | H4: Pass | I4: $ .venv/bin/python -m pytest 'qa/tests/test_backend_live.py::test_BE_003_azure_mode_missing_settings' → exit 0 cd Code/backend && CHATBOT_MODE=azure .venv/bin/python -m uvicorn chatbot.main:app --port 49911
A5: BE-004 | B5: Backend | C5: Medium | D5: Config – invalid | E5: Start with CHATBOT_MODE=bogus, RATE_LIMIT_PER_MINUTE=abc, MAX_UPLOAD_MB=lots, SEARCH_TOP_K=-5, MAX_HISTORY_TURNS=x, ALLOW_DOCUMENT_UPLOAD=maybe. | F5: No crash: either a clear error or a working app with safe defaults. | G5: started=True; config={'title': 'AI Based Chatbot', 'subtitle': 'AI based chatbot platform', 'mode': 'local', 'authMode': 'none', 'uploadEnabled': False, 'maxUploadMb': 16}; chat=200; invalid values silently replaced by defaults (no warning in log: True) | H5: Pass | I5: $ .venv/bin/python -m pytest 'qa/tests/test_backend_live.py::test_BE_004_invalid_config_values' → exit 0 cd Code/backend && CHATBOT_MODE=bogus RATE_LIMIT_PER_MINUTE=abc MAX_UPLOAD_MB=lots SEARCH_TOP_K=-5 MAX_HISTORY_TURNS=x ALLOW_DOCUMENT_UPLOAD=maybe .venv/bin/python -m uvicorn chatbot.main:app --port 40667
A6: BE-005 | B6: Backend | C6: Medium | D6: Config – auth mode | E6: Start with AUTH_MODE=pasword (typo) and DEMO_PASSWORD set; call /api/chat and / without signing in. | F6: Unknown auth mode is rejected or fails closed (sign-in still required). | G6: started=True; authMode reported='pasword'; unauthenticated chat=200; GET / = 200 (chat page and API open without sign-in, Sign out button hidden) Assertion: AssertionError: AUTH_MODE typo silently disables sign-in (fails open) | H6: Fail | I6: $ .venv/bin/python -m pytest 'qa/tests/test_backend_live.py::test_BE_005_unrecognised_auth_mode_fails_closed' → exit 1 cd Code/backend && AUTH_MODE=pasword DEMO_PASSWORD=<test-value> .venv/bin/python -m uvicorn chatbot.main:app --port 33043 | J6: DEF-03
A7: BE-006 | B7: Backend | C7: High | D7: Auth – not configured | E7: AUTH_MODE=password with no DEMO_PASSWORD; POST /api/login; POST /api/chat. | F7: Login 503 not_configured; chat 401 (gate fails closed). | G7: login 503 {"error":{"code":"not_configured","message":"Sign-in is not configured yet: the demo password is missing or not readable from Key Vault."}}; chat 401 | H7: Pass | I7: $ .venv/bin/python -m pytest 'qa/tests/test_backend_api.py::test_BE_006_password_mode_without_password' → exit 0
A8: BE-007 | B8: Backend | C8: High | D8: Health | E8: GET /healthz. | F8: 200 with status=ok, version, mode. | G8: 200 {"status":"ok","version":"1.0.0","mode":"local","searchSetup":"not-applicable"} | H8: Pass | I8: $ .venv/bin/python -m pytest 'qa/tests/test_backend_api.py::test_BE_007_healthz' → exit 0 GET /healthz
A9: BE-008 | B9: Backend | C9: Low | D9: Config endpoint | E9: GET /api/config. | F9: 200 with title, subtitle, mode, authMode, uploadEnabled, maxUploadMb. | G9: 200 {"title":"AI Based Chatbot","subtitle":"AI based chatbot platform","mode":"local","authMode":"none","uploadEnabled":true,"maxUploadMb":16} | H9: Pass | I9: $ .venv/bin/python -m pytest 'qa/tests/test_backend_api.py::test_BE_008_config' → exit 0
A10: BE-009 | B10: Backend | C10: Critical | D10: Chat – happy path | E10: POST /api/chat {"message":"How do I return a product?","history":[]}. | F10: 200 JSON {answer: non-empty string, citations: [{id,title,snippet}]}. | G10: 200; answer[:160]='Unused products in their original packaging can be returned within 14 days of delivery for a full refund. [1] Care Plus costs 8 percent of the product price and'; citations=['returns-and-refunds.md', 'warranty-policy.md']; 0.005s | H10: Pass | I10: $ .venv/bin/python -m pytest 'qa/tests/test_backend_api.py::test_BE_009_chat_valid' → exit 0 POST /api/chat {"message":"How do I return a product?","history":[]}
A11: BE-010 | B11: Backend | C11: High | D11: Validation – empty | E11: POST /api/chat {"message":""}. | F11: 422 {error:{code:invalid_request,message}}, no stack trace. | G11: empty: 422 {"error":{"code":"invalid_request","message":"message: String should have at least 1 character"}} | H11: Pass | I11: $ .venv/bin/python -m pytest 'qa/tests/test_backend_api.py::test_BE_010_empty_message' → exit 0
A12: BE-011 | B12: Backend | C12: High | D12: Validation – whitespace | E12: POST message ' ' and '\n\t \n'. | F12: 422 invalid_request. | G12: ' ': 422 {"error":{"code":"invalid_request","message":"message: Value error, message must not be blank"}} | '\n\t \n': 422 {"error":{"code":"invalid_request","message":"message: Value error, message must not be blank"}} | H12: Pass | I12: $ .venv/bin/python -m pytest 'qa/tests/test_backend_api.py::test_BE_011_whitespace_message' → exit 0
A13: BE-012 | B13: Backend | C13: High | D13: Validation – length | E13: POST messages of 4,000, 4,001 and 100,000 characters. | F13: 4,000 → 200; 4,001 and 100,000 → 422. | G13: 4000 chars -> 200; 4001 -> 422 {"error":{"code":"invalid_request","message":"message: String should have at most 4000 characters"}}; 100000 -> 422 | H13: Pass | I13: $ .venv/bin/python -m pytest 'qa/tests/test_backend_api.py::test_BE_012_message_length_limit' → exit 0
A14: BE-013 | B14: Backend | C14: Medium | D14: Validation – special chars | E14: POST messages with HTML/script, SQL, quotes/backslashes, NUL byte, template syntax, ../ paths. | F14: 200 well-formed answer each time, no 500. | G14: '<script>alert(1)</script> warr': 200 | "'; DROP TABLE users; -- warran": 200 | 'warranty \\ " \' ` $ % & * { } [': 200 | 'warranty\x00null byte': 200 | '{{7*7}} ${7*7} warranty': 200 | '../../etc/passwd warranty': 200 | H14: Pass | I14: $ .venv/bin/python -m pytest 'qa/tests/test_backend_api.py::test_BE_013_special_characters' → exit 0
A15: BE-014 | B15: Backend | C15: Medium | D15: Validation – emoji | E15: POST mixed emoji question and emoji-only message. | F15: 200 each, non-empty answer. | G15: mixed: 200 'The warranty does not cover damage caused by misuse, power surges, incorrect ins'; emoji-only: 200 'I could not find this in the available documents. Try rephrasing the question, o' | H15: Pass | I15: $ .venv/bin/python -m pytest 'qa/tests/test_backend_api.py::test_BE_014_emoji' → exit 0
A16: BE-015 | B16: Backend | C16: Medium | D16: Validation – non-English | E16: POST questions in Hindi, Chinese, Spanish, Russian, Arabic. | F16: 200 each, non-empty answer, no 500. | G16: वारंटी में क्या शामिल है?: 200 answer='I could not find this in the available documents. Try rephrasing the question, or add a do' | 保修范围包括什么？: 200 answer='I could not find this in the available documents. Try rephrasing the question, or add a do' | ¿Qué cubre la garantía?: 200 answer='I could not find this in the available documents. Try rephrasing the question, or add a do' | Что покрывает гарантия?: 200 answer='I could not find this in the available documents. Try rephrasing the question, or add a do' | ما الذي يغطيه الضمان؟: 200 answer='I could not find this in the available documents. Try rephrasing the question, or add a do' | H16: Pass | I16: $ .venv/bin/python -m pytest 'qa/tests/test_backend_api.py::test_BE_015_non_english' → exit 0
A17: BE-016 | B17: Backend | C17: High | D17: Validation – malformed JSON | E17: POST truncated JSON, plain text, trailing comma, empty body, null, [] with content-type JSON. | F17: Clean 4xx JSON error, no 500/stack trace. | G17: '{"message": "hi"': 422 {"error":{"code":"invalid_request","message":"16: JSON decode error"}} | 'not json': 422 {"error":{"code":"invalid_request","message":"0: JSON decode error"}} | '{"message": "hi",}': 422 {"error":{"code":"invalid_request","message":"17: JSON decode error"}} | '': 422 {"error":{"code":"invalid_request","message":"Field required"}} | 'null': 422 {"error":{"code":"invalid_request","message":"Field required"}} | '[]': 422 {"error":{"code":"invalid_request","message":"Input should be a valid dictionary or object to extract fields from"}} | H17: Pass | I17: $ .venv/bin/python -m pytest 'qa/tests/test_backend_api.py::test_BE_016_malformed_json' → exit 0
A18: BE-017 | B18: Backend | C18: High | D18: Validation – missing/wrong fields | E18: POST {}, history only, message as number/null/list, history as string, history item without content. | F18: 422 invalid_request for each. | G18: {}: 422 {"error":{"code":"invalid_request","message":"message: Field required"}} | {"history": []}: 422 {"error":{"code":"invalid_request","message":"message: Field required"}} | {"message": 123}: 422 {"error":{"code":"invalid_request","message":"message: Input should be a valid string"}} | {"message": null}: 422 {"error":{"code":"invalid_request","message":"message: Input should be a valid string"}} | {"message": ["a"]}: 422 {"error":{"code":"invalid_request","message":"message: Input should be a valid string"}} | {"message": "hi", "history": "x"}: 422 {"error":{"code":"invalid_request","message":"history: Input should be a valid list"}} | {"message": "hi", "history": [{"role": "user"}]}: 422 {"error":{"code":"invalid_request","message":"history.0.content: Field required"}} | H18: Pass | I18: $ .venv/bin/python -m pytest 'qa/tests/test_backend_api.py::test_BE_017_missing_or_wrong_type_fields' → exit 0
... A29: BE-028 | B29: Backend | C29: High | D29: Auth – cookie flags | E29: Login over http and with X-Forwarded-Proto: https; inspect Set-Cookie; chat with cookie. | F29: HttpOnly and SameSite=Lax always; Secure on https; chat 200. | G29: login 200; http Set-Cookie: chatbot_session=<token>; HttpOnly; Max-Age=43200; Path=/; SameSite=lax; https Set-Cookie: chatbot_session=<token>; HttpOnly; Max-Age=43200; Path=/; SameSite=lax; Secure; chat with cookie 200 | H29: Pass | I29: $ .venv/bin/python -m pytest 'qa/tests/test_backend_api.py::test_BE_028_login_sets_secure_cookie' → exit 0
A30: BE-029 | B30: Backend | C30: Medium | D30: Auth – logout | E30: Login, copy cookie, POST /api/logout, replay the copied cookie. | F30: Replayed cookie rejected (session revoked) → 401. | G30: logout 200; chat after logout (cookie dropped) 401; replay of pre-logout cookie -> 200 Assertion: AssertionError: token still valid after logout (no server-side revocation) | H30: Fail | I30: $ .venv/bin/python -m pytest 'qa/tests/test_backend_api.py::test_BE_029_logout_revokes_session' → exit 1 | J30: DEF-01
A31: BE-030 | B31: Backend | C31: High | D31: Auth – upload key | E31: UPLOAD_API_KEY set; list/upload/delete with no key, wrong key, right key. | F31: 401 without/with wrong key; 201/200/200 with the right key. | G31: {"list no key": 401, "list wrong key": 401, "upload no key": 401, "delete wrong key": 401, "upload right key": 201, "list right key": 200, "delete right key": 200} | H31: Pass | I31: $ .venv/bin/python -m pytest 'qa/tests/test_backend_api.py::test_BE_030_upload_key_enforced' → exit 0
A32: BE-031 | B32: Backend | C32: High | D32: LLM failure – timeout | E32: Real openai SDK via mock transport raising ReadTimeout. | F32: 502 upstream_error, friendly message, fast return, no secrets/stack trace. | G32: 502 {"error":{"code":"upstream_error","message":"The service could not answer right now. Please try again shortly."}} in 0.07s | H32: Pass | I32: $ .venv/bin/python -m pytest 'qa/tests/test_backend_llm_failures.py::test_BE_031_llm_timeout' → exit 0 mock transport raises httpx.ReadTimeout
A33: BE-032 | B33: Backend | C33: High | D33: LLM failure – 429 | E33: Mock transport returns 429. | F33: 503 busy with friendly message. | G33: 503 {"error":{"code":"busy","message":"The language model is busy right now. Please try again in a moment."}} in 0.00s | H33: Pass | I33: $ .venv/bin/python -m pytest 'qa/tests/test_backend_llm_failures.py::test_BE_032_llm_rate_limited' → exit 0
A34: BE-033 | B34: Backend | C34: High | D34: LLM failure – 5xx | E34: Mock transport returns 500/502/503. | F34: 502 upstream_error with friendly message. | G34: upstream 500 -> 502 {"error":{"code":"upstream_error","message":"The service could not answer right now. Please try again shortly."}} in 0.00s | upstream 502 -> 502 {"error":{"code":"upstream_error","message":"The service could not answer right now. Please try again shortly."}} in 0.00s | upstream 503 -> 502 {"error":{"code":"upstream_error","message":"The service could not answer right now. Please try again shortly."}} in 0.00s | H34: Pass | I34: $ .venv/bin/python -m pytest 'qa/tests/test_backend_llm_failures.py::test_BE_033_llm_server_error' → exit 0
A35: BE-034 | B35: Backend | C35: Medium | D35: LLM failure – empty | E35: Mock returns content '', null, ' '. | F35: 200 with fallback text 'I could not produce an answer…'. | G35: content='' -> 200 {"answer":"I could not produce an answer. Please try rephrasing the question.","citations":[]} | content=None -> 200 {"answer":"I could not produce an answer. Please try rephrasing the question.","citations":[]} | content=' ' -> 200 {"answer":"I could not produce an answer. Please try rephrasing the question.","citations":[]} | H35: Pass | I35: $ .venv/bin/python -m pytest 'qa/tests/test_backend_llm_failures.py::test_BE_034_llm_empty_response' → exit 0
A36: BE-035 | B36: Backend | C36: Medium | D36: LLM failure – malformed | E36: Mock returns non-JSON body, JSON without choices, empty choices, truncated JSON. | F36: Clean JSON 5xx with friendly message, no stack trace, no hang. | G36: non-JSON body -> 500 {"error":{"code":"internal_error","message":"Something went wrong. Please try again."}} in 0.02s | JSON without choices -> 500 {"error":{"code":"internal_error","message":"Something went wrong. Please try again."}} in 0.01s | empty choices -> 500 {"error":{"code":"internal_error","message":"Something went wrong. Please try again."}} in 0.01s | truncated JSON -> 500 {"error":{"code":"internal_error","message":"Something went wrong. Please try again."}} in 0.02s | H36: Pass | I36: $ .venv/bin/python -m pytest 'qa/tests/test_backend_llm_failures.py::test_BE_035_llm_malformed_response' → exit 0
A37: BE-036 | B37: Backend | C37: Medium | D37: LLM failure – content filter | E37: Mock returns 400 content_filter, and finish_reason=content_filter. | F37: 400 content_filtered with friendly message. | G37: prompt filtered -> 400 {"error":{"code":"content_filtered","message":"The question was blocked by the content filter. Please rephrase it."}}; answer filtered -> 400 {"error":{"code":"content_filtered","message":"The answer was blocked by the content filter. Please rephrase the question."}} | H37: Pass | I37: $ .venv/bin/python -m pytest 'qa/tests/test_backend_llm_failures.py::test_BE_036_llm_content_filter' → exit 0
A38: BE-037 | B38: Backend | C38: High | D38: LLM failure – hang | E38: Use the app's production client settings against a socket that accepts but never replies. | F38: Error returned in bounded time (< App Service's 230 s limit), never hangs forever. | G38: production client timeout=60.0, max_retries=2; non-responding LLM -> UpstreamError (HTTP 502) after 181.5s (3 connection attempts). Front end fetch has no timeout, so the user waits this long. | H38: Pass | I38: $ .venv/bin/python -m pytest 'qa/tests/test_backend_llm_failures.py::test_BE_037_hung_llm_is_bounded' → exit 0
A39: BE-038 | B39: Backend | C39: Medium | D39: Search failure | E39: AI Search client via mock transport: 500, 503, 429, 403, connect timeout. | F39: 502 upstream_error or 503 busy with friendly message. | G39: search 500 -> 502 {"error":{"code":"upstream_error","message":"The service could not answer right now. Please try again shortly."}} in 0.00s | search 503 -> 503 {"error":{"code":"busy","message":"Azure AI Search is busy. Try again in a moment."}} in 0.00s | search 429 -> 503 {"error":{"code":"busy","message":"Azure AI Search is busy. Try again in a moment."}} in 0.00s | search 403 -> 502 {"error":{"code":"upstream_error","message":"The service could not answer right now. Please try again shortly."}} in 0.00s | search timeout -> 502 {"error":{"code":"upstream_error","message":"The service could not answer right now. Please try again shortly."}} in 0.00s | H39: Pass | I39: $ .venv/bin/python -m pytest 'qa/tests/test_backend_llm_failures.py::test_BE_038_search_failures' → exit 0
A40: BE-039 | B40: Backend | C40: High | D40: RAG – answerable | E40: Ask 'What does the warranty cover?' (local retriever + extractive stand-in). | F40: Answer quotes the warranty doc with [1]; citation title warranty-policy.md. | G40: answer='The warranty does not cover damage caused by misuse, power surges, incorrect installation, or repairs carried out by anyone other than a Northwind authorised service partner. [1] Repairs outside the w'; citations=[(1, 'warranty-policy.md'), (2, 'customer-support.md')] | H40: Pass | I40: $ .venv/bin/python -m pytest 'qa/tests/test_backend_api.py::test_BE_039_answerable_question_cites_source' → exit 0
A41: BE-040 | B41: Backend | C41: High | D41: RAG – unanswerable | E41: Ask 'What is the capital of France?' and a 2018 football question. | F41: 'Could not find' response, no citations, nothing invented. | G41: 'What is the capital of France?' -> answer='I could not find this in the available documents. Try rephrasing the question, or add a document that covers it. (Local mode: answers are extracts, not generate'; citations=[] | 'Who won the 2018 FIFA football tournament?' -> answer='I could not find this in the available documents. Try rephrasing the question, or add a document that covers it. (Local mode: answers are extracts, not generate'; citations=[] | H41: Pass | I41: $ .venv/bin/python -m pytest 'qa/tests/test_backend_api.py::test_BE_040_unanswerable_question' → exit 0
A42: BE-041 | B42: Backend | C42: High | D42: RAG – live grounding | E42: With live Azure OpenAI + AI Search: fixed question set, check grounding/citations/'not found'. | F42: Answers grounded and cited; unanswerable questions refused. | G42: BLOCKED: answer quality/grounding/'I don't know' behaviour of the real model needs Azure OpenAI + AI Search | H42: Blocked | I42: $ .venv/bin/python -m pytest 'qa/tests/test_backend_api.py::test_BE_041_live_grounding_quality' → exit skipped (5 if run alone)
... A58: BE-057 | B58: Backend | C58: Medium | D58: Rate limiting | E58: RATE_LIMIT_PER_MINUTE=20; send 23 requests. | F58: First 20 → 200, then 429 rate_limited. | G58: 22 requests -> 20x200, 2x429 (first 429 at #21); body={"error":{"code":"rate_limited","message":"Too many questions in a short time. Please wait a minute."}} | H58: Pass | I58: $ .venv/bin/python -m pytest 'qa/tests/test_backend_api.py::test_BE_057_rate_limit' → exit 0
A59: BE-058 | B59: Backend | C59: Medium | D59: Rate limiting – spoofing | E59: Send 30 chats and 12 wrong logins, each with a different X-Forwarded-For. | F59: Limits still apply to the real client (429s appear, lockout triggers). | G59: 30 chats from one client with rotating X-Forwarded-For -> 0x429; 12 wrong logins rotating XFF -> 0x429 (lockout never triggered) Assertion: AssertionError: per-IP rate limit bypassed by a client-supplied X-Forwarded-For header | H59: Fail | I59: $ .venv/bin/python -m pytest 'qa/tests/test_backend_api.py::test_BE_058_rate_limit_spoofed_forwarded_for' → exit 1 | J59: DEF-02
A60: BE-059 | B60: Backend | C60: Medium | D60: CORS | E60: Preflight and POST from Origin https://evil.example. | F60: No Access-Control-Allow-Origin (same-origin only). | G60: preflight 405, ACAO=None; cross-origin POST ACAO=None | H60: Pass | I60: $ .venv/bin/python -m pytest 'qa/tests/test_backend_api.py::test_BE_059_cors' → exit 0
A61: BE-060 | B61: Backend | C61: Medium | D61: Security headers | E61: GET /, /app.js, /api/config, /healthz. | F61: CSP (script-src 'self', frame-ancestors 'none'), X-Frame-Options DENY, nosniff, Referrer-Policy; no-store on pages/API. | G61: {"/": {"content-security-policy": "default-src 'self'; img-src 'self' data:; style-src 'self'; script-src 'self'; connect-src 'self'; frame-ancestors 'none'; base-uri 'none'; form-action 'self'", "x-frame-options": "DENY", "x-content-type-options": "nosniff", "referrer-policy": "no-referrer", "cache-control": "no-store", "strict-transport-security": null}, "/app.js": {"content-security-policy": "default-src 'self'; img-src 'self' data:; style-src 'self'; script-src 'self'; connect-src 'self'; frame-ancestors 'none'; base-uri 'none'; form-action 'self'", "x-frame-options": "DENY", "x-content-type-options": "nosniff", "referrer-policy": "no-referrer", "cache-control": null, "strict-transport-security": null}, "/api/config": {"content-security-policy": "default-src 'self'; img-src 'self' data:; style-src 'self'; script-src 'self'; connect-src 'self'; frame-ancestors 'none'; base-uri 'none'; | H61: Pass | I61: $ .venv/bin/python -m pytest 'qa/tests/test_backend_api.py::test_BE_060_security_headers' → exit 0
A62: BE-061 | B62: Backend | C62: Low | D62: CLI | E62: `python -m chatbot ask "What does the warranty cover?"` in local mode. | F62: Exit 0, answer with [1] and the source title. | G62: exit 0: 'The warranty does not cover damage caused by misuse, power surges, incorrect installation, or repairs carried out by anyone other than a Northwind authorised service partner. [1] Repairs outside the w' | H62: Pass | I62: $ .venv/bin/python -m pytest 'qa/tests/test_backend_live.py::test_BE_061_cli_ask' → exit 0 cd Code/backend && python -m chatbot ask "What does the warranty cover?"
A63: BE-062 | B63: Backend | C63: Low | D63: Docker | E63: `docker build` the repo Dockerfile, run, call /healthz and /api/chat. | F63: Image builds; container healthy; chat 200. | G63: build ok; container healthz=True {"status":"ok","version":"1.0.0","mode":"local","searchSetup":"not-applicable"}; chat=200 | H63: Pass | I63: $ .venv/bin/python -m pytest 'qa/tests/test_backend_live.py::test_BE_062_docker_image' → exit 0 docker build -t qa-ai-based-chatbot:test . && docker run -p 48933:8000 qa-ai-based-chatbot:test
A64: BE-063 | B64: Backend | C64: Medium | D64: Validation – huge body | E64: POST a ~4.8 MB JSON body (600 history items). | F64: Fast 422, no 500/hang. | G64: 4.8 MB body -> 422 in 0.02s: {"error":{"code":"invalid_request","message":"history: List should have at most 40 items after validation, not 600"}} | H64: Pass | I64: $ .venv/bin/python -m pytest 'qa/tests/test_backend_api.py::test_BE_063_very_large_body' → exit 0
A65: BE-064 | B65: Backend | C65: Low | D65: Unknown routes | E65: GET /api/does-not-exist; PUT /api/chat. | F65: 404/405, no stack trace. | G65: GET unknown -> 404 {"detail":"Not Found"}; PUT /api/chat -> 405 {"detail":"Method Not Allowed"} | H65: Pass | I65: $ .venv/bin/python -m pytest 'qa/tests/test_backend_api.py::test_BE_064_unknown_route' → exit 0
...

Sheet Defects
A1: ID | B1: Severity | C1: Layer | D1: Title | E1: Steps to reproduce | F1: Expected vs Actual | G1: Affected test IDs | H1: Likely cause (analysis only)
A2: DEF-01 | B2: Medium | C2: Backend | D2: Logout does not revoke the session token | E2: AUTH_MODE=password; sign in; copy the chatbot_session cookie; POST /api/logout; send the copied cookie to /api/chat. | F2: Expected: Token rejected after logout. Actual: 200 – the copied token stays valid for up to 12 hours. | G2: BE-029 | H2: auth.py issues a stateless `expiry.HMAC` token; /api/logout only deletes the cookie in the browser. No server-side revocation (denylist/session version).
A3: DEF-02 | B3: Medium | C3: Backend | D3: Rate limit and login lockout can be bypassed with a forged X-Forwarded-For header | E3: Send >20 chats/min or >5 wrong passwords, each with a different X-Forwarded-For value. | F3: Expected: Requests from one client are limited (429) and lockout triggers. Actual: 0 × 429 for 30 chats; lockout never triggered for 12 wrong passwords. | G3: BE-058 | H3: main.py client_ip() trusts the first X-Forwarded-For entry from any caller. Local runs and Docker are affected. On App Service it depends on whether the front end overwrites or appends to that header; if it appends, production is affected too.
A4: DEF-03 | B4: Medium | C4: Backend | D4: Unrecognised AUTH_MODE value silently turns sign-in off (fails open) | E4: Start with AUTH_MODE=pasword (typo) and DEMO_PASSWORD set; open / and POST /api/chat with no cookie. | F4: Expected: Startup error, or sign-in still required. Actual: App starts; chat page and API are open (200); /api/config reports authMode 'pasword'; Sign out button is hidden. | G4: BE-005 | H4: main.py builds the password gate only when auth_mode == 'password'; config.py does not check AUTH_MODE against the allowed values. The ARM template uses a dropdown, so the risk is mainly manual or .env setups.
A5: DEF-04 | B5: Medium | C5: UI | D5: A question typed while an answer is loading is silently discarded | E5: Ask a question; while 'Searching the documents…' is shown, type a second question and press Enter. | F5: Expected: Second question is kept (queued, sent later, or left in the box). Actual: Input box is cleared, nothing is sent and the text is lost. | G5: UI-021 | H5: app.js submit handler clears the textarea before calling ask(); ask() returns early when busy. Only the Send button is disabled, so Enter still submits.
A6: DEF-05 | B6: Low | C6: UI | D6: Follow-ups fail after an answer longer than 8,000 characters | E6: Receive an answer over 8,000 characters, then ask any follow-up. | F6: Expected: Follow-up answered. Actual: Error 'history.1.content: String should have at most 8000 characters'. Every later question fails until New conversation. | G6: UI-023 | H6: main.py ChatMessage.content max_length=8000, but app.js resends full previous answers as history. CHAT_MAX_TOKENS=2000 makes such answers rare but possible. The raw validation text is shown to the user.
A7: DEF-06 | B7: Low | C7: Backend | D7: Malformed upstream replies return 500 internal_error, not the documented 502 upstream_error | E7: Make Azure OpenAI return 200 with empty `choices`, or AI Search return 200 with a non-JSON body. | F7: Expected: 502 upstream_error (Documents/local-development.md). Actual: 500 internal_error ('Something went wrong'). Server log shows an 'Unhandled error' traceback. The user still gets a friendly message. | G7: BE-065 (graceful handling itself passes: BE-035) | H7: llm.py reads response.choices[0] outside the try/except; search.py calls response.json() without catching JSON errors.
A8: DEF-07 | B8: Low | C8: Front end | D8: Upload key stored in clear text in sessionStorage | E8: Open Documents, type an upload key; inspect sessionStorage. | F8: Expected: Secret not kept in web storage. Actual: sessionStorage['chatbot.uploadKey'] holds the key in clear text for the tab's lifetime. | G8: FE-014 | H8: app.js stores the key with storage.set(KEY_KEY, …) for convenience. Exposure is limited by the strict CSP (script-src 'self') and tab scope.

Sheet Not Tested & Out of Scope
A1: ID | B1: Type / Status | C1: Priority | D1: Item | E1: Reason
A2: BE-021 | B2: Blocked | C2: High | D2: Conversation – live recall | E2: BLOCKED: no Azure OpenAI credentials in this environment (live LLM needed to judge recall)
A3: BE-041 | B3: Blocked | C3: High | D3: RAG – live grounding | E3: BLOCKED: answer quality/grounding/'I don't know' behaviour of the real model needs Azure OpenAI + AI Search
A4: BE-049 | B4: Blocked | C4: High | D4: Safety – prompt injection (live) | E4: BLOCKED: resistance of the real model to prompt injection / system-prompt extraction needs live Azure OpenAI
A5: — | B5: Out of scope | C5: — | D5: Streaming responses (UI-007) | E5: Not implemented: /api/chat returns one JSON response.
A6: — | B6: Out of scope | C6: — | D6: Stop / regenerate / copy / thumbs up-down (UI-024) | E6: No such controls in the UI.
A7: — | B7: Out of scope | C7: — | D7: Tools / function calling | E7: The chatbot has no tools or function calling.
A8: — | B8: Out of scope | C8: — | D8: Server-side history list/delete endpoints; cross-user conversation access | E8: No server-side storage: conversations live in the browser tab. BE-024 confirms no such endpoint exists.
A9: — | B9: Out of scope | C9: — | D9: Expired/invalid OAuth or JWT, per-user accounts | E9: Only a single shared demo password exists; its token cases are covered by BE-027.
A10: — | B10: Out of scope | C10: — | D10: Live Azure mode end to end (Azure OpenAI, AI Search, Blob, Key Vault, App Insights) | E10: No credentials, and live runs cost money. Live-model quality tests BE-021, BE-041 and BE-049 are Blocked.
A11: — | B11: Out of scope | C11: — | D11: Infrastructure / deployment (Bicep, ARM, deploy scripts) | E11: Not part of chatbot behaviour. Partly covered by the existing test_deployment.py in BE-001.
A12: — | B12: Out of scope | C12: — | D12: Markdown code blocks and hyperlinks in replies | E12: Not a designed feature (app.js supports only bold, lists and [n]). UI-020 records that they show as plain text.
... A23: — | B23: Observation | C23: — | D23: Note | E23: The textarea's own outline is removed; its focus indicator is the composer border changing to the brand colour (FE-011).
